<?xml version='1.0'?>
<sdf version='1.4'>
<world name="default">
        <include>
            <uri>model://sun</uri>
        </include>
        <include>
            <uri>model://ground_plane</uri>
        </include>
<!--pioneer with kinect-->
<model name="RosAria">
<pose>0 -10.0 0.16 0 0 0</pose>	
      <link name="chassis">
        <pose>0 0 0.16 0 0 0</pose>			
        <inertial>
          <mass>200.0</mass>
        </inertial>
        <collision name="collision">
          <geometry>
            <box>
              <size>0.445 0.277 0.17</size>
            </box>
          </geometry>
        </collision>
        <collision name="castor_collision">
          <pose>-0.200 0 -0.12 0 0 0</pose>
          <geometry>
            <sphere>
              <radius>0.04</radius>
            </sphere>
          </geometry>
          <surface>
            <friction>
              <ode>
                <mu>0</mu>
                <mu2>0</mu2>
                <slip1>1.0</slip1>
                <slip2>1.0</slip2>
              </ode>
            </friction>
          </surface>
        </collision>
        <visual name="visual">
          <pose>0 0 0.04 0 0 0</pose>
          <geometry>
            <mesh>
              <uri>model://pioneer2dx/meshes/chassis.dae</uri>
            </mesh>
          </geometry>
        </visual>
        <visual name="castor_visual">
          <pose>-0.200 0 -0.12 0 0 0</pose>
          <geometry>
            <sphere>
              <radius>0.04</radius>
            </sphere>
          </geometry>
          <material>
            <script>
              <uri>file://media/materials/scripts/gazebo.material</uri>
              <name>Gazebo/FlatBlack</name>
            </script>
          </material>
        </visual>
      </link>
      <link name="right_wheel">
        <pose>0.1 -.17 0.11 0 1.5707 1.5707</pose>         <!--change-->
        <inertial>
          <mass>0.5</mass>
        </inertial>
        <collision name="collision">
          <geometry>
            <cylinder>
              <radius>0.11</radius>
              <length>0.05</length>
            </cylinder>
          </geometry>
          <surface>
            <friction>
              <ode>
                <mu>100000.0</mu>
                <mu2>100000.0</mu2>
                <slip1>0.0</slip1>
                <slip2>0.0</slip2>
              </ode>
            </friction>
          </surface>
        </collision>
        <visual name="visual">
          <geometry>
            <cylinder>
              <radius>0.11</radius>
              <length>0.05</length>
            </cylinder>
          </geometry>
          <material>
            <script>
              <uri>file://media/materials/scripts/gazebo.material</uri>
              <name>Gazebo/FlatBlack</name>
            </script>
          </material>
        </visual>
      </link>
      <link name="left_wheel">
        <pose>0.1 .17 0.11 0 1.5707 1.5707</pose>    <!--change-->
        <inertial>
          <mass>0.5</mass>
        </inertial>
        <collision name="collision">
          <geometry>
            <cylinder>
              <radius>0.11</radius>
              <length>0.05</length>
            </cylinder>
          </geometry>
          <surface>
            <friction>
              <ode>
                <mu>100000.0</mu>
                <mu2>100000.0</mu2>
                <slip1>0.0</slip1>
                <slip2>0.0</slip2>
              </ode>
            </friction>
          </surface>
        </collision>
        <visual name="visual">
          <geometry>
            <cylinder>
              <radius>0.11</radius>
              <length>0.05</length>
            </cylinder>
          </geometry>
          <material>
            <script>
              <uri>file://media/materials/scripts/gazebo.material</uri>
              <name>Gazebo/FlatBlack</name>
            </script>
          </material>
        </visual>
      </link>
      <joint type="revolute" name="left_wheel_hinge">
        <pose>0 0 -0.03 0 0 0</pose>
        <child>left_wheel</child>
        <parent>chassis</parent>
        <axis>
          <xyz>0 1 0</xyz>
        </axis>
      </joint>
      <joint type="revolute" name="right_wheel_hinge">
        <pose>0 0 0.03 0 0 0</pose>
        <child>right_wheel</child>
        <parent>chassis</parent>
        <axis>
          <xyz>0 1 0</xyz>
        </axis>
      </joint> 
      <plugin name="differential_drive_controller" filename="libgazebo_ros_diff_drive.so">
        <alwaysOn>true</alwaysOn>
	<updateRate>30</updateRate>
	<leftJoint>left_wheel_hinge</leftJoint>
	<rightJoint>right_wheel_hinge</rightJoint>
	<wheelSeparation>0.34</wheelSeparation>
	<wheelDiameter>0.11</wheelDiameter>
        <wheelTorque>100</wheelTorque>
	<commandTopic>cmd_vel</commandTopic>
	<odometryTopic>odom</odometryTopic>
	<odometryFrame>odom</odometryFrame>
	<robotBaseFrame>base_footprint</robotBaseFrame>
      </plugin>

      <link name="kinect">
      <pose>0.0 0 0.31 0 0 0</pose>
        <inertial>
          <mass>0.1</mass>
        </inertial>
        <collision name="collision">
          <geometry>
            <box>
              <size>0.073000 0.276000 0.072000</size>
            </box>
          </geometry>
        </collision>
      	<visual name="visual">
	  <geometry>
	    <mesh>
	      <uri>model://kinect/meshes/kinect.dae</uri>
	    </mesh>
	  </geometry>
        </visual>
        <sensor name="camera" type="depth">
          <update_rate>20</update_rate>
            <camera>
	      <horizontal_fov>1.047198</horizontal_fov>
	      <image>
	        <width>640</width>
	        <height>480</height>
	        <format>R8G8B8</format>
	      </image>
	      <clip>
	        <near>0.5</near>
	        <far>5</far>
	      </clip>
	    </camera>
	    <plugin name="$kinect_controller" filename="libgazebo_ros_openni_kinect.so">
	      <baseline>0.2</baseline>
	      <alwaysOn>true</alwaysOn>
    	      <updateRate>30.0</updateRate>
	      <cameraName>camera</cameraName>
	      <imageTopicName>/camera/rgb/image_raw</imageTopicName>
	      <cameraInfoTopicName>/camera/rgb/camera_info</cameraInfoTopicName>
	      <depthImageTopicName>/camera/depth/image_raw</depthImageTopicName>
	      <depthImageCameraInfoTopicName>/camera/depth/camera_info</depthImageCameraInfoTopicName>
	      <pointCloudTopicName>/camera/depth/points</pointCloudTopicName>
	      <frameName>camera_link</frameName>
	      <pointCloudCutoff>0.4</pointCloudCutoff>
	      <distortionK1>0.00000001</distortionK1>
	      <distortionK2>0.00000001</distortionK2>
	      <distortionK3>0.00000001</distortionK3>
	      <distortionT1>0.00000001</distortionT1>
	      <distortionT2>0.00000001</distortionT2>
	      <CxPrime>0</CxPrime>
	      <Cx>0</Cx>
	      <Cy>0</Cy>
	      <focalLength>0</focalLength>
	      <hackBaseline>0</hackBaseline>
	    </plugin>
      </sensor>
    </link>
      <joint type="revolute" name="kinect_hinge">
<pose>0 0 0.03 0 0 0</pose>
        <child>kinect</child>
        <parent>chassis</parent>
        <axis>
          <xyz>0 0 1</xyz>
    <limit>
      <upper>0</upper>
      <lower>0</lower>
    </limit>
        </axis>
      </joint>

    </model>

  <model name='real_world_map'>
    <link name='Wall_1'>
      <collision name='Wall_1_Collision'>
        <geometry>
          <box>
            <size>3.26 0.2 2.5</size>
          </box>
        </geometry>
        <pose>0 0 1.25 0 -0 0</pose>
      </collision>
      <visual name='Wall_1_Visual'>
        <pose>0 0 1.25 0 -0 0</pose>
        <geometry>
          <box>
            <size>3.26 0.2 2.5</size>
          </box>
        </geometry>
        <material>
          <script>
            <uri>file://media/materials/scripts/gazebo.material</uri>
            <name>Gazebo/Grey</name>
          </script>
        </material>
      </visual>
      <velocity_decay>
        <linear>0</linear>
        <angular>0</angular>
      </velocity_decay>
      <pose>0.412843 -2.08389 0 0 -0 0</pose>
    </link>
    <link name='Wall_10'>
      <collision name='Wall_10_Collision'>
        <geometry>
          <box>
            <size>1.14446 0.2 2.5</size>
          </box>
        </geometry>
        <pose>0 0 1.25 0 -0 0</pose>
      </collision>
      <visual name='Wall_10_Visual'>
        <pose>0 0 1.25 0 -0 0</pose>
        <geometry>
          <box>
            <size>1.14446 0.2 2.5</size>
          </box>
        </geometry>
        <material>
          <script>
            <uri>file://media/materials/scripts/gazebo.material</uri>
            <name>Gazebo/Grey</name>
          </script>
        </material>
      </visual>
      <velocity_decay>
        <linear>0</linear>
        <angular>0</angular>
      </velocity_decay>
      <pose>0.049596 -1.62455 0 0 0 -1.5708</pose>
    </link>
    <link name='Wall_12'>
      <collision name='Wall_12_Collision'>
        <geometry>
          <box>
            <size>1.03952 0.2 2.5</size>
          </box>
        </geometry>
        <pose>0 0 1.25 0 -0 0</pose>
      </collision>
      <visual name='Wall_12_Visual'>
        <pose>0 0 1.25 0 -0 0</pose>
        <geometry>
          <box>
            <size>1.03952 0.2 2.5</size>
          </box>
        </geometry>
        <material>
          <script>
            <uri>file://media/materials/scripts/gazebo.material</uri>
            <name>Gazebo/Grey</name>
          </script>
        </material>
      </visual>
      <velocity_decay>
        <linear>0</linear>
        <angular>0</angular>
      </velocity_decay>
      <pose>0.067086 0.526732 0 0 0 -1.5708</pose>
    </link>
    <link name='Wall_13'>
      <collision name='Wall_13_Collision'>
        <geometry>
          <box>
            <size>1.19693 0.2 2.5</size>
          </box>
        </geometry>
        <pose>0 0 1.25 0 -0 0</pose>
      </collision>
      <visual name='Wall_13_Visual'>
        <pose>0 0 1.25 0 -0 0</pose>
        <geometry>
          <box>
            <size>1.19693 0.2 2.5</size>
          </box>
        </geometry>
        <material>
          <script>
            <uri>file://media/materials/scripts/gazebo.material</uri>
            <name>Gazebo/Grey</name>
          </script>
        </material>
      </visual>
      <velocity_decay>
        <linear>0</linear>
        <angular>0</angular>
      </velocity_decay>
      <pose>0.565553 0.10697 0 0 -0 0</pose>
    </link>
    <link name='Wall_14'>
      <collision name='Wall_14_Collision'>
        <geometry>
          <box>
            <size>1.09199 0.2 2.5</size>
          </box>
        </geometry>
        <pose>0 0 1.25 0 -0 0</pose>
      </collision>
      <visual name='Wall_14_Visual'>
        <pose>0 0 1.25 0 -0 0</pose>
        <geometry>
          <box>
            <size>1.09199 0.2 2.5</size>
          </box>
        </geometry>
        <material>
          <script>
            <uri>file://media/materials/scripts/gazebo.material</uri>
            <name>Gazebo/Grey</name>
          </script>
        </material>
      </visual>
      <velocity_decay>
        <linear>0</linear>
        <angular>0</angular>
      </velocity_decay>
      <pose>1.06402 0.552967 0 0 -0 1.5708</pose>
    </link>
    <link name='Wall_16'>
      <collision name='Wall_16_Collision'>
        <geometry>
          <box>
            <size>1.19693 0.2 2.5</size>
          </box>
        </geometry>
        <pose>0 0 1.25 0 -0 0</pose>
      </collision>
      <visual name='Wall_16_Visual'>
        <pose>0 0 1.25 0 -0 0</pose>
        <geometry>
          <box>
            <size>1.19693 0.2 2.5</size>
          </box>
        </geometry>
        <material>
          <script>
            <uri>file://media/materials/scripts/gazebo.material</uri>
            <name>Gazebo/Grey</name>
          </script>
        </material>
      </visual>
      <velocity_decay>
        <linear>0</linear>
        <angular>0</angular>
      </velocity_decay>
      <pose>0.548063 1.01645 0 0 -0 0</pose>
    </link>
    <link name='Wall_3'>
      <collision name='Wall_3_Collision'>
        <geometry>
          <box>
            <size>4.36027 0.2 2.5</size>
          </box>
        </geometry>
        <pose>0 0 1.25 0 -0 0</pose>
      </collision>
      <visual name='Wall_3_Visual'>
        <pose>0 0 1.25 0 -0 0</pose>
        <geometry>
          <box>
            <size>4.36027 0.2 2.5</size>
          </box>
        </geometry>
        <material>
          <script>
            <uri>file://media/materials/scripts/gazebo.material</uri>
            <name>Gazebo/Grey</name>
          </script>
        </material>
      </visual>
      <velocity_decay>
        <linear>0</linear>
        <angular>0</angular>
      </velocity_decay>
      <pose>2.07226 0.002969 0 0 -0 1.5708</pose>
    </link>
    <link name='Wall_4'>
      <collision name='Wall_4_Collision'>
        <geometry>
          <box>
            <size>3.38138 0.2 2.5</size>
          </box>
        </geometry>
        <pose>0 0 1.25 0 -0 0</pose>
      </collision>
      <visual name='Wall_4_Visual'>
        <pose>0 0 1.25 0 -0 0</pose>
        <geometry>
          <box>
            <size>3.38138 0.2 2.5</size>
          </box>
        </geometry>
        <material>
          <script>
            <uri>file://media/materials/scripts/gazebo.material</uri>
            <name>Gazebo/Grey</name>
          </script>
        </material>
      </visual>
      <velocity_decay>
        <linear>0</linear>
        <angular>0</angular>
      </velocity_decay>
      <pose>0.481564 2.08311 0 0 -0 3.14159</pose>
    </link>
    <link name='Wall_5'>
      <collision name='Wall_5_Collision'>
        <geometry>
          <box>
            <size>4.29909 0.2 2.5</size>
          </box>
        </geometry>
        <pose>0 0 1.25 0 -0 0</pose>
      </collision>
      <visual name='Wall_5_Visual'>
        <pose>0 0 1.25 0 -0 0</pose>
        <geometry>
          <box>
            <size>4.29909 0.2 2.5</size>
          </box>
        </geometry>
        <material>
          <script>
            <uri>file://media/materials/scripts/gazebo.material</uri>
            <name>Gazebo/Grey</name>
          </script>
        </material>
      </visual>
      <velocity_decay>
        <linear>0</linear>
        <angular>0</angular>
      </velocity_decay>
      <pose>-1.10913 0.033559 0 0 0 -1.5708</pose>
    </link>
    <link name='Wall_8'>
      <collision name='Wall_8_Collision'>
        <geometry>
          <box>
            <size>1.14446 0.2 2.5</size>
          </box>
        </geometry>
        <pose>0 0 1.25 0 -0 0</pose>
      </collision>
      <visual name='Wall_8_Visual'>
        <pose>0 0 1.25 0 -0 0</pose>
        <geometry>
          <box>
            <size>1.14446 0.2 2.5</size>
          </box>
        </geometry>
        <material>
          <script>
            <uri>file://media/materials/scripts/gazebo.material</uri>
            <name>Gazebo/Grey</name>
          </script>
        </material>
      </visual>
      <velocity_decay>
        <linear>0</linear>
        <angular>0</angular>
      </velocity_decay>
      <pose>0.994059 -1.62455 0 0 -0 1.5708</pose>
    </link>
    <link name='Wall_99'>
      <collision name='Wall_99_Collision'>
        <geometry>
          <box>
            <size>1.03952 0.2 2.5</size>
          </box>
        </geometry>
        <pose>0 0 1.25 0 -0 0</pose>
      </collision>
      <visual name='Wall_99_Visual'>
        <pose>0 0 1.25 0 -0 0</pose>
        <geometry>
          <box>
            <size>1.03952 0.2 2.5</size>
          </box>
        </geometry>
        <material>
          <script>
            <uri>file://media/materials/scripts/gazebo.material</uri>
            <name>Gazebo/Grey</name>
          </script>
        </material>
      </visual>
      <velocity_decay>
        <linear>0</linear>
        <angular>0</angular>
      </velocity_decay>
      <pose>0.533543 -0.526732 0 0 0 -1.5708</pose>
    </link>
    <link name='Wall_9'>
      <collision name='Wall_9_Collision'>
        <geometry>
          <box>
            <size>1.14446 0.2 2.5</size>
          </box>
        </geometry>
        <pose>0 0 1.25 0 -0 0</pose>
      </collision>
      <visual name='Wall_9_Visual'>
        <pose>0 0 1.25 0 -0 0</pose>
        <geometry>
          <box>
            <size>1.14446 0.2 2.5</size>
          </box>
        </geometry>
        <material>
          <script>
            <uri>file://media/materials/scripts/gazebo.material</uri>
            <name>Gazebo/Grey</name>
          </script>
        </material>
      </visual>
      <velocity_decay>
        <linear>0</linear>
        <angular>0</angular>
      </velocity_decay>
      <pose>0.521828 -1.15231 0 0 -0 3.14159</pose>
    </link>
    <static>1</static>
  </model>
</world>
</sdf>
